Workbook
Name CT_Diabetes: Lists!$E$2:$E$7
Name FMT_Longevity: Lists!$O$2:$O$20
Name FMT_Obesity: Lists!$L$2:$L$9
Name Pillars_List: Lists!$A$2:$A$6
Name CT_Kids: Lists!$G$2:$G$6
Name All_ContentTypes: Lists!$T$2:$T$23
Name Avatars_List: Lists!$C$2:$C$8
Name CT_Obesity: Lists!$F$2:$F$5
Name FMT_Diabetes: Lists!$K$2:$K$18
Name FMT_Nutrition_Myths: Lists!$N$2:$N$4
Name CT_Nutrition_Myths: Lists!$H$2
Name CT_Longevity: Lists!$I$2:$I$7
Name FMT_Kids: Lists!$M$2:$M$16
Name All_Formats: Lists!$U$2:$U$63

Sheet How To Use
B1: Instagram Analytics Tracker — How This Works
B3: 1. Where You Enter Data
B4: Go to the 'Manual Entry' sheet — it's the ONLY sheet you touch. Fill in Date, Title, Caption, then pick Content Pillar from the dropdown. Content Type and Format dropdowns will automatically filter to match your chosen Pillar. Post Type (Reel/Carousel) fills in automatically based on the Format you pick — you never set it manually. Then enter Views, Likes, Comments, Shares, Saves and Accounts Reached. Every other sheet updates instantly.
B6: 2. How 'Best Reel' / 'Best Carousel' Is Calculated
B7: Raw totals aren't compared directly (a Reel with huge Views but no engagement isn't automatically 'best'). Instead, each post is scored on 5 metrics — Views, Like Rate, Comment Rate, Share Rate and Save Rate (rates are relative to Accounts Reached, so posts that reach fewer people aren't unfairly penalized). Each metric is converted to a percentile rank against similar posts in the same period, then combined into a single weighted score: Reels: 20% Views + 15% Likes + 25% Comments + 25% Shares + 15% Saves Carousels: 10% Views + 10% Likes + 20% Comments + 30% Shares + 30% Saves Carousels weight Shares and Saves higher because people share/save carousels for reference far more than Reels — that's the strongest quality signal for that format.
B9: 3. What Each Sheet Shows
B10: • Overall Analytics — totals, best pillar, best avatar, engagement rate • Best Reels / Best Carousels — this week's & this month's winner, plus weekly leaderboard, monthly leaderboard, and all-time Top 20 ranking • Monthly Comparison — previous vs current month, growth %, best pillar/avatar per month • Dashboard — one-page overview with KPIs, top performers, and charts
B12: 4. Capacity & Extending It
B13: The tracker supports up to 500 posts out of the box, and leaderboards cover the most recent 60 weeks and 30 months. If you outgrow this, the formulas can be dragged down further — just ask and it can be expanded.
B15: 5. A Note on Color Coding
B16: Blue text = manual input. Green text = automatic formulas. Never type over green cells — they recalculate on their own.

Sheet Dashboard
A1: 📊 Instagram Analytics Dashboard
A2: Complete overview — pulls live from all other sheets. Do not edit this sheet.
A4: Total Posts | C4: Total Reels | E4: Total Carousels | G4: Total Views | I4: Total Accounts Reached | K4: Overall Engagement Rate | N4: Pillar | O4: Views
A5: ='Overall Analytics'!A5 -> 36 | C5: ='Overall Analytics'!B5 -> 16 | E5: ='Overall Analytics'!C5 -> 20 | G5: ='Overall Analytics'!D5 -> 3710594 | I5: ='Overall Analytics'!D8 -> 2985004 | K5: ='Overall Analytics'!E8 -> 0.044303793 | N5: Diabetes | O5: ='Overall Analytics'!C15 -> 179771
N6: Obesity | O6: ='Overall Analytics'!C16 -> 0
A7: This Week & This Month — Top Performers | N7: Kids | O7: ='Overall Analytics'!C17 -> 0
A8: Best Reel — This Week | D8: Best Carousel — This Week | G8: Best Reel — This Month | J8: Best Carousel — This Month | N8: Nutrition Myths | O8: ='Overall Analytics'!C18 -> 87042
A9: ='Best Reels'!A5 -> Not treating Diabetes, only managaing symptoms | D9: ='Best Carousels'!A5 -> Indian sitting for a whole day | G9: ='Best Reels'!F5 -> Tips for Effective sleep | J9: ='Best Carousels'!F5 -> Indian sitting for a whole day | N9: Longevity | O9: ='Overall Analytics'!C19 -> 0
A11: ='Monthly Comparison'!A26 -> Views declined 0.0% vs last month. Top pillar this month: Diabetes. Top avatar this month: Diabetes Patient. | N11: Avatar | O11: Views
N12: Diabetes Patient | O12: ='Overall Analytics'!C26 -> 0
N13: Parents | O13: ='Overall Analytics'!C27 -> 0
N14: Working Professional | O14: ='Overall Analytics'!C28 -> 0
N15: Senior Adult | O15: ='Overall Analytics'!C29 -> 0
N16: Health Enthusiast | O16: ='Overall Analytics'!C30 -> 0
N17: Weight Loss | O17: ='Overall Analytics'!C31 -> 0
N18: Womens | O18: ='Overall Analytics'!C32 -> 0
N20: Month | O20: Views
N21: =TEXT(EDATE(TODAY(),-11),"MMM-YY") -> Aug-25 | O21: =SUMIF(Calc!$C$2:$C$501,TEXT(EDATE(TODAY(),-11),"YYYY-MM"),Calc!$I$2:$I$501) -> 0
N22: =TEXT(EDATE(TODAY(),-10),"MMM-YY") -> Sep-25 | O22: =SUMIF(Calc!$C$2:$C$501,TEXT(EDATE(TODAY(),-10),"YYYY-MM"),Calc!$I$2:$I$501) -> 0
N23: =TEXT(EDATE(TODAY(),-9),"MMM-YY") -> Oct-25 | O23: =SUMIF(Calc!$C$2:$C$501,TEXT(EDATE(TODAY(),-9),"YYYY-MM"),Calc!$I$2:$I$501) -> 0
N24: =TEXT(EDATE(TODAY(),-8),"MMM-YY") -> Nov-25 | O24: =SUMIF(Calc!$C$2:$C$501,TEXT(EDATE(TODAY(),-8),"YYYY-MM"),Calc!$I$2:$I$501) -> 0
N25: =TEXT(EDATE(TODAY(),-7),"MMM-YY") -> Dec-25 | O25: =SUMIF(Calc!$C$2:$C$501,TEXT(EDATE(TODAY(),-7),"YYYY-MM"),Calc!$I$2:$I$501) -> 0
N26: =TEXT(EDATE(TODAY(),-6),"MMM-YY") -> Jan-26 | O26: =SUMIF(Calc!$C$2:$C$501,TEXT(EDATE(TODAY(),-6),"YYYY-MM"),Calc!$I$2:$I$501) -> 0
N27: =TEXT(EDATE(TODAY(),-5),"MMM-YY") -> Feb-26 | O27: =SUMIF(Calc!$C$2:$C$501,TEXT(EDATE(TODAY(),-5),"YYYY-MM"),Calc!$I$2:$I$501) -> 0
N28: =TEXT(EDATE(TODAY(),-4),"MMM-YY") -> Mar-26 | O28: =SUMIF(Calc!$C$2:$C$501,TEXT(EDATE(TODAY(),-4),"YYYY-MM"),Calc!$I$2:$I$501) -> 0
N29: =TEXT(EDATE(TODAY(),-3),"MMM-YY") -> Apr-26 | O29: =SUMIF(Calc!$C$2:$C$501,TEXT(EDATE(TODAY(),-3),"YYYY-MM"),Calc!$I$2:$I$501) -> 0
N30: =TEXT(EDATE(TODAY(),-2),"MMM-YY") -> May-26 | O30: =SUMIF(Calc!$C$2:$C$501,TEXT(EDATE(TODAY(),-2),"YYYY-MM"),Calc!$I$2:$I$501) -> 0
N31: =TEXT(EDATE(TODAY(),-1),"MMM-YY") -> Jun-26 | O31: =SUMIF(Calc!$C$2:$C$501,TEXT(EDATE(TODAY(),-1),"YYYY-MM"),Calc!$I$2:$I$501) -> 2269476
N32: =TEXT(EDATE(TODAY(),-0),"MMM-YY") -> Jul-26 | O32: =SUMIF(Calc!$C$2:$C$501,TEXT(EDATE(TODAY(),-0),"YYYY-MM"),Calc!$I$2:$I$501) -> #REF!

Sheet Manual Entry
A1: Date | B1: Reel/Carousel Title | C1: Caption | D1: Content Pillar | E1: Content Type | F1: Format | G1: Post Type (Auto) | H1: Audience Avatar | I1: Views | J1: Likes | K1: Comments | L1: Shares | M1: Saves | N1: Accounts Reached
A2: 46174 | B2: 15 Minutes Night Routine for Diabetics | C2: 🚨 Diabetes Patients… Don’t Skip This 15-Minute Night Routine! Morning walking is good… but what if I told you there’s a more powerful habit for controlling blood sugar? 👀 After dinner, just walk for 15 minutes inside your home or on your terrace. When your leg muscles start moving, they use the excess sugar in your blood for energy. 🩸➡️⚡ Experts say this simple habit can help reduce sugar levels by 20–30 points consistently. Small daily actions like this can become a major step in your diabetes reversal journey. 💪 A healthy lifestyle without depending completely on medicines is possible — when you follow the right scientifically-backed habits. Comment “SUGAR” below 🍬 I’ll send you the details directly to your inbox. 📩 diabetes reversal, night walking, blood sugar control, post dinner walk, diabetes management, sugar reduction, healthy lifestyle, insulin sensitivity, walking after dinner, natural diabetes control, diabetes tips, scientific health habits" #Diabetes #HealthTips #HealthyLifestyle #FitnessMotivation #WellnessJourney #DiabetesCare #BloodSugarControl #WalkingBenefits #DiabetesManagement #InsulinResistance #SugarControl #HealthyHabits #LifestyleMedicine #PostDinnerWalk #NaturalHealing #NightWalking #DiabetesReversalJourney #ReverseDiabetesNaturally #SugarLevelControl #15MinuteWalk #TerraceWalking #IndianHealthTips #PrediabetesCare #MedicineFreeLifestyle #GlucoseManagement | D2: Diabetes | F2: Talking Head with or without Props | G2: {=IF(F2="","",IFERROR(INDEX(Lists!$R:$R,MATCH(F2,Lists!$Q:$Q,0)),"Check Format"))} -> Reel | I2: 37506 | J2: 384 | K2: 113 | L2: 243 | M2: 137 | N2: 29623
A3: 46175 | B3: Summer Hydration Guide | C3: 💧 Are you drinking enough water this summer... or just guessing? Hydration needs change with age, weather, pregnancy, and even how much you sweat. From babies to older adults, staying hydrated is one of the simplest ways to protect your health during hot summer months. ☀️ Quick hydration check: 🟡 Pale yellow urine = Well hydrated 🟠 Dark yellow = Time to drink water ⚪ Colourless = You may be overhydrated Save this guide for your family and make sure everyone stays hydrated this summer! 💙 👇 Which summer drink is your favorite? 🥥 Tender Coconut Water 🥛 Buttermilk 🍉 Watermelon Juice 🍋 Lemon Water 🌾 Ragi Koozh #Hydration #HealthyLifestyle #SummerHealth #DrinkWater #WellnessJourney HydrationTips | F3: Carousel - Answering Questions | G3: {=IF(F3="","",IFERROR(INDEX(Lists!$R:$R,MATCH(F3,Lists!$Q:$Q,0)),"Check Format"))} -> Carousel | I3: 42918 | J3: 82 | K3: 10 | L3: 12 | M3: 18 | N3: 18758
A4: 46176 | B4: 5 health habits that cost zero rupees | C4: Your health doesn’t change with expensive supplements… It changes with simple daily habits. 💯 These 5 FREE habits can improve your energy, sleep, sugar levels, and overall health starting from tomorrow👇 ✅ Walk 10 minutes after every meal ✅ Eat vegetables & protein before rice ✅ Drink water before meals ✅ No phone 30 mins before sleep ✅ Get sunlight within 10 mins of waking up ☀️ Small habits. Massive results. Most people know WHAT to do… But consistency starts when habits become simple and practical. Save this reel and start following at least ONE habit today. ❤️ Share this with your friends & family who want a healthier life. #HealthyLifestyle #HealthTips #Wellness #FitnessMotivation #HealthyLiving | D4: Nutrition Myths | F4: Talking Head with or without Props | G4: {=IF(F4="","",IFERROR(INDEX(Lists!$R:$R,MATCH(F4,Lists!$Q:$Q,0)),"Check Format"))} -> Reel | I4: 30952 | J4: 542 | K4: 15 | L4: 225 | M4: 243 | N4: 22416
A5: 46177 | B5: 5 Indian Spices supporting Blood sugar | C5: 🚨 Blood sugar control may be hiding in your kitchen! 🌿 These 5 Indian spices have been clinically studied for their potential role in supporting healthy blood sugar levels: ✅ Fenugreek (Vendhayam) ✅ Cinnamon (Pattai) ✅ Ginger (Inji) ✅ Amla (Nellikai) ✅ Turmeric (Manjal) From slowing sugar absorption to supporting insulin sensitivity, these everyday ingredients may offer additional support alongside a healthy lifestyle. 💚 blood sugar control, diabetes management, Indian spices, fenugreek benefits, cinnamon for diabetes, ginger benefits, amla health benefits, turmeric benefits, insulin sensitivity, glucose metabolism, diabetic diet, natural blood sugar support #diabetes #healthtips #healthylifestyl #nutrition #wellnes #bloodsugarcontrol #DiabetesAwareness #HealthyEating #PreventiveHealth #naturalremedies #insulinsensitivity #glucosecontrol #diabeticdiet #functionalnutrition #fenugreekbenefits #cinnamonbenefits #gingerforhealth #amlabenefit #TurmericBenefits #IndianSpices #bloodsugarsupport #diabeteseducation #healthyglucose #doctorfarmer | D5: Diabetes | F5: Carousel - Answering Questions | G5: {=IF(F5="","",IFERROR(INDEX(Lists!$R:$R,MATCH(F5,Lists!$Q:$Q,0)),"Check Format"))} -> Carousel | I5: 142265 | J5: 781 | K5: 3 | L5: 842 | M5: 890 | N5: 72659
A6: 46178 | B6: ICMR Warning about Coffee on Empty Stomach | C6: ☕ Drinking tea or coffee first thing in the morning? You may want to rethink that. According to ICMR guidelines, having tea or coffee on an empty stomach can increase acidity and may contribute to stomach-related issues. Excess caffeine and sugar can also affect blood sugar levels and reduce calcium absorption. ✅ Drink fewer cups ✅ Avoid tea or coffee on an empty stomach ✅ Have it after a meal instead Small changes in your daily routine can make a big difference to your long-term health. 📌 Save this post for later and share it with every tea & coffee lover in your family! ☕❤️ #HealthTips #HealthyLifestyle #Wellness #Nutrition #HealthyLiving #TeaLovers #CoffeeLovers #MorningRoutine #DigestiveHealth #BloodSugarControl #AcidityRelief #GutHealth #HealthyHabits #PreventiveHealth #NutritionTips #ICMR #EmptyStomachTea #EmptyStomachCoffee #CaffeineAwareness #HealthyMorningHabits #TeaAndHealth #CoffeeAndHealth #IndianHealthTips #DoctorFarmer #DailyHealthAdvice | D6: Nutrition Myths | F6: Talking Head with or without Props | G6: {=IF(F6="","",IFERROR(INDEX(Lists!$R:$R,MATCH(F6,Lists!$Q:$Q,0)),"Check Format"))} -> Reel | I6: 56090 | J6: 649 | K6: 24 | L6: 632 | M6: 142 | N6: 44171
A7: 46179 | B7: Breakfast is doing more harm than good | C7: 🚨 Your breakfast might be doing more harm than good! Most people think they're starting the day healthy, but one simple breakfast mistake could be causing energy crashes, constant hunger, weight gain, and even increasing the risk of diabetes. The good news? You don't have to give up your favorite foods. A few smart changes and adding more protein can help you stay full longer, reduce cravings, and support better overall health. 💪🥚🥗 Save this reel so you can make healthier breakfast choices every morning! 📌 👉 Follow for more simple health and nutrition tips every day. | F7: Talking Head with or without Props | G7: {=IF(F7="","",IFERROR(INDEX(Lists!$R:$R,MATCH(F7,Lists!$Q:$Q,0)),"Check Format"))} -> Reel | I7: 36691 | J7: 529 | K7: 12 | L7: 131 | M7: 142 | N7: 27905
A8: 46180 | B8: ICMR Warning about Coffee on Empty Stomach | C8: ☕️Stop drinking tea or coffee on an empty stomach! According to recent guidelines from the Indian Council of Medical Research (ICMR), starting your day with tea or coffee before eating may increase acidity, digestive discomfort, and ulcer-related issues. Not only that, excess caffeine and sugar can contribute to blood sugar spikes and may affect calcium absorption over time. Simple fix: • Reduce your daily tea/coffee intake • Have it after a meal instead of on an empty stomach • Make small changes that support long-term health Your morning habits matter more than you think. Tag a tea or coffee lover who needs to see this and share this with your friends and family! | F8: Carousel - Answering Questions | G8: {=IF(F8="","",IFERROR(INDEX(Lists!$R:$R,MATCH(F8,Lists!$Q:$Q,0)),"Check Format"))} -> Carousel | I8: 74186 | J8: 289 | K8: 10 | L8: 521 | M8: 144 | N8: 34846
A9: 46182 | B9: Lack of Sleep increase blood sugar more than rice | C9: 🚨 Think rice is the biggest reason your sugar levels are high? What if I told you that just ONE night of poor sleep can raise your blood sugar even more? 😳 When you don't sleep properly, your body produces a stress hormone called cortisol. This hormone signals your liver to release stored sugar into your bloodstream, causing your sugar levels to spike the very next morning. Diabetes is not just about food. Sleep, stress, activity, and lifestyle habits all play a major role. The good news? When you understand the real reasons behind high blood sugar and make the right lifestyle changes, better control is possible. Let's find the root cause and create a plan that works for you. ❤️ #Diabetes #HealthTips #HealthyLifestyle #BloodSugar #WellnessJourney #DiabetesManagement #BloodSugarControl #Type2Diabetes #DiabetesAwareness #HealthyLivingTips #MetabolicHealth | F9: Talking Head with or without Props | G9: {=IF(F9="","",IFERROR(INDEX(Lists!$R:$R,MATCH(F9,Lists!$Q:$Q,0)),"Check Format"))} -> Reel | I9: 19516 | J9: 174 | K9: 16 | L9: 109 | M9: 59 | N9: 15538
A10: 46183 | B10: Night walking better than Morning walking | C10: 🚶‍♂️ Most people with diabetes focus only on morning walks... But what if a simple 15-minute walk after dinner could help lower your blood sugar more effectively? 🌙 When you walk after your evening meal, your leg muscles use excess glucose from your bloodstream as energy. This can help reduce post-meal sugar spikes and support better blood sugar management. 📉 Small daily habits create big health transformations. Consistency is the key to your diabetes reversal journey. 💙 Want to learn more science-backed strategies to reduce sugar levels naturally and move towards a medicine-free lifestyle? #Diabetes #HealthTips #HealthyLifestyle #WellnessJourney | F10: Carousel - Answering Questions | G10: {=IF(F10="","",IFERROR(INDEX(Lists!$R:$R,MATCH(F10,Lists!$Q:$Q,0)),"Check Format"))} -> Carousel | I10: 115377 | J10: 864 | K10: 4 | L10: 757 | M10: 426 | N10: 60745
A11: 46184 | B11: 3 Mistakes in Morning Breakfast | C11: 🚨 Your breakfast may be the reason you're always hungry! Most people think they're eating a healthy breakfast... but 9 out of 10 are making a mistake that can lead to frequent hunger, weight gain, and even diabetes. 🍽️ Starting your day with only idli, dosa, chapati, or puri can cause blood sugar spikes and make you crave snacks within hours. ✅ The solution? Add more protein to your breakfast! Eggs, sundal, vegetables, and balanced portions of your favorite foods can keep you full longer, reduce junk food cravings, and support better health. Save this post for your next breakfast 🍳 and share it with someone who needs to know this! Follow for more simple health tips every day. 💙 | F11: Carousel - Answering Questions | G11: {=IF(F11="","",IFERROR(INDEX(Lists!$R:$R,MATCH(F11,Lists!$Q:$Q,0)),"Check Format"))} -> Carousel | I11: 156047 | J11: 1207 | K11: 24 | L11: 1051 | M11: 609 | N11: 87310
A12: 46185 | B12: Lack of Sleep increase blood sugar more than rice | C12: 🍚 Think rice is the biggest reason your sugar levels go up? What if I told you that just ONE night of poor sleep can raise your blood sugar even more? When you don't sleep properly, your body releases a stress hormone called cortisol. This hormone signals your liver to release stored sugar into your bloodstream, causing your glucose levels to spike the very next morning. Diabetes is not just about food. Sleep, stress, hormones, and lifestyle all play a major role. The good news? When you understand the real causes and make the right lifestyle changes, transformation becomes possible. #Diabetes #HealthTips #HealthyLifestyle #Wellness #BloodSugar #DiabetesAwareness #BloodSugarControl #InsulinResistance #GlucoseManagement #HealthyLiving | F12: Carousel - Answering Questions | G12: {=IF(F12="","",IFERROR(INDEX(Lists!$R:$R,MATCH(F12,Lists!$Q:$Q,0)),"Check Format"))} -> Carousel | I12: 46509 | J12: 118 | K12: 4 | L12: 69 | M12: 56 | N12: 21065
A13: 46186 | B13: Fruit mistakes diabetics make | C13: 🍎 Same fruit. Different impact. Most people think eating an apple and drinking apple juice are the same. They’re not. When you eat a whole fruit, you get the natural fiber that helps slow down sugar absorption and supports better blood sugar control. When you drink fruit juice, much of that fiber is removed, allowing sugar to enter the bloodstream much faster. The lesson isn't to fear fruit—it's to understand the right way to consume it. Choose whole fruits more often than fruit juices for better metabolic health, stable energy, and improved glucose management. 💪 #HealthyLifestyle #Nutrition #DiabetesAwareness #HealthTips #WellnessJourney #BloodSugarControl #HealthyEatingHabits #MetabolicHealth #NutritionEducation | F13: Talking Head with or without Props | G13: {=IF(F13="","",IFERROR(INDEX(Lists!$R:$R,MATCH(F13,Lists!$Q:$Q,0)),"Check Format"))} -> Reel | I13: 25691 | J13: 243 | K13: 8 | L13: 52 | M13: 69 | N13: 19955
A14: 46187 | B14: Fruit mistakes diabetics make | C14: ⚠️ The biggest mistake people make with fruits... Many people avoid junk food but unknowingly drink their fruits every day. Here’s the problem👇 🍎 When you eat a whole apple, the fiber acts like a natural brake, slowing how quickly sugar enters your bloodstream. 🥤 When you drink apple juice, that protective fiber is largely missing, allowing sugar to hit your blood much faster. The fruit isn’t the problem. The way you consume it matters. Small daily choices can have a big impact on your energy levels, blood sugar, and long-term health. Choose the fruit. Skip the juice when possible. 💯 💬 What’s your favorite fruit? Tell me in the comments! #HealthEducation #HealthyLiving #NutritionTips #Wellness #DiabetesAwareness BloodSugar HealthyChoices NutritionCoach HealthyHabits MetabolicHealth GlucoseControl HealthyDietTips FiberBenefits EatRealFood | F14: Carousel - Answering Questions | G14: {=IF(F14="","",IFERROR(INDEX(Lists!$R:$R,MATCH(F14,Lists!$Q:$Q,0)),"Check Format"))} -> Carousel | I14: 76815 | J14: 348 | K14: 0 | L14: 97 | M14: 168 | N14: 32251
A15: 46189 | B15: Ragi - Kids Best drink for growth | C15: 🚨 Stop spending on expensive health drinks when nature already has a better option for your kids! Ragi is a nutritional powerhouse packed with calcium, iron, and essential B vitamins that support healthy growth, stronger bones, and better dental development. 💪🦴✨ Instead of relying only on commercial health drinks, try adding a homemade ragi drink with jaggery to your child's daily routine. It's simple, nutritious, and rooted in traditional wisdom. 🌾 Small food choices today can create healthier, stronger kids tomorrow. 👉 Do you give ragi to your children? Share your favorite ragi recipe in the comments below! #HealthyKids #KidsNutrition #HealthyEating #ParentingTips #NutritionMatters #RagiBenefits #MilletPower #HealthyParenting | F15: Talking Head with or without Props | G15: {=IF(F15="","",IFERROR(INDEX(Lists!$R:$R,MATCH(F15,Lists!$Q:$Q,0)),"Check Format"))} -> Reel | I15: 54358 | J15: 699 | K15: 21 | L15: 948 | M15: 434 | N15: 40298
A16: 46190 | B16: Ragi - Kids Best drink for growth | C16: Stop spending money on health drinks without knowing this... There’s a traditional superfood that can be even more nutritious for your child than many popular malt-based drinks. 🌾 Ragi is packed with nutrients and contains significantly more calcium than milk, along with iron and essential B vitamins. When prepared with natural jaggery and included regularly in your child's diet, it can support: ✅ Strong bones ✅ Healthy growth ✅ Better dental development ✅ Overall nutrition Sometimes the best nutrition isn't found in a packet—it's already in our traditional foods. Have you tried giving ragi to your kids? Share your experience in the comments 👇 and save this post for other parents! #HealthyKids #Nutrition #HealthyEating #ParentingTips #KidsHealth #Ragi #Millets #HealthyFoodForKids #ChildNutrition #HealthyParenting | F16: Carousel - Answering Questions | G16: {=IF(F16="","",IFERROR(INDEX(Lists!$R:$R,MATCH(F16,Lists!$Q:$Q,0)),"Check Format"))} -> Carousel | I16: 222837 | J16: 2798 | K16: 34 | L16: 4646 | M16: 1892 | N16: 195887
A17: 46191 | B17: Tips for Effective sleep | C17: 😴 Still struggling to sleep at night? Most people think insomnia is a nighttime problem. But the real solution starts long before bedtime. ✅ Reset your body clock ✅ Avoid bright white lights after 7 PM ✅ Keep your bedroom completely dark ✅ Stay active in the evening ✅ Avoid afternoon naps Small changes in your daily routine can dramatically improve your sleep quality and help your body produce melatonin naturally. Good sleep isn't a luxury—it's the foundation of your health. 🌙✨ Which of these sleep hacks are you going to try tonight? Let me know in the comments below! 👇 Save this reel and share it with someone who struggles with sleep. 💙 #SleepTips #Insomnia #HealthyLifestyle #WellnessJourney #HealthTips #BetterSleep #SleepHealth #SleepRoutine #DeepSleep #CircadianRhythm | F17: Talking Head with or without Props | G17: {=IF(F17="","",IFERROR(INDEX(Lists!$R:$R,MATCH(F17,Lists!$Q:$Q,0)),"Check Format"))} -> Reel | I17: 35037 | J17: 296 | K17: 18 | L17: 175 | M17: 122 | N17: 26493
A18: 46192 | B18: 4 Truths about Periods Blood | C18: 🩸 உங்கள் மாதவிடாய் ரத்தம் வெறும் ரத்தப்போக்கு அல்ல... அது உங்கள் ஹார்மோன்கள், ஊட்டச்சத்து நிலை, மன அழுத்தம் மற்றும் உடல்நலத்தைப் பற்றி முக்கியமான தகவல்களை சொல்லும் ஒரு சிக்னல். 👩‍⚕️ ✔️ 3 நாட்களுக்கும் குறைவான மாதவிடாய் ✔️ அதிக ரத்தப்போக்கும் கட்டிகளும் ✔️ மாதவிடாய்க்கு முன்பே ரத்தக் கசிவு ✔️ ஒழுங்கற்ற சுழற்சி ✔️ அதிக வலியுடன் வரும் மாதவிடாய் இவை அனைத்திற்கும் உடல் ஏதோ ஒரு காரணத்தை காட்டிக்கொண்டு இருக்கலாம். இந்த carousel-ஐ முழுவதும் படித்து, உங்கள் உடல் சொல்லும் செய்தியை புரிந்துகொள்ளுங்கள். 💜 📌 இந்த பதிவை சேமித்து வையுங்கள். 📤 பெண்கள் அனைவருக்கும் பகிருங்கள். 💬 உங்களுடைய மாதவிடாய் அனுபவம் இதில் எதனுடன் தொடர்புடையது என்பதை கமெண்டில் சொல்லுங்கள். #HormoneHealth #PeriodHealth #WomensHealth #HealthyHormones #TamilHealth #MyHealthSchool | F18: Carousel - Answering Questions | G18: {=IF(F18="","",IFERROR(INDEX(Lists!$R:$R,MATCH(F18,Lists!$Q:$Q,0)),"Check Format"))} -> Carousel | I18: 627556 | J18: 11155 | K18: 113 | L18: 25253 | M18: 13194 | N18: 870241
... A36: 46211 | B36: 1 in 11 in India have Diabetes | C36: 🚨 1 in 11 Indians already have Diabetes. 1 in 6 could be next… and many don't even know it. Diabetes doesn't appear overnight—it develops silently for years before your blood test detects it. If you think "I'm not overweight, so I'm safe," think again. Many Indians develop insulin resistance even at a normal BMI. Watch for the early warning signs: ⚠️ Dark neck or underarms ⚠️ Sugar cravings after meals The good news? Small lifestyle changes can make a big difference: 🥗 Eat salad → protein → carbs 🚶 Walk for 10 minutes after meals Early awareness is your biggest advantage. Don't wait until diabetes finds you—take action before it's too late. For Appointments: +91 89259 54625 +91 72004 24271 | F36: Carousel - Answering Questions | G36: {=IF(F36="","",IFERROR(INDEX(Lists!$R:$R,MATCH(F36,Lists!$Q:$Q,0)),"Check Format"))} -> Carousel | I36: 82305 | J36: 314 | K36: 5 | L36: 259 | M36: 297 | N36: 35364
A37: 46212 | B37: 5 Foods harming Your Thyroid | C37: 🚨 உங்கள் தைராய்டை மெதுவாக பாதிக்கும் உணவுகள்... நீங்கள் தினமும் சாப்பிடுகிறீர்களா? 😨 தைராய்டு பிரச்சினை மருந்தால் மட்டும் கட்டுப்படாது. நீங்கள் தினமும் சாப்பிடும் சில உணவுகள் அயோடின் பயன்பாட்டைத் தடுக்கவும், ஹார்மோன் உற்பத்தியை பாதிக்கவும், தன்னெதிர்ப்பு (Autoimmune) தாக்குதல்களை அதிகரிக்கவும் காரணமாக இருக்கலாம். ❌ அதிக சோயா ❌ அதிகமாக பச்சையாக சாப்பிடும் முட்டைக்கோஸ், காலிஃபிளவர், ப்ரோக்கோலி ❌ Ultra-processed & packaged foods ❌ Bromine உள்ள "Diet" foods ❌ அதிக Fluoride அதற்கு பதிலாக, செலினியம், ஜிங்க் மற்றும் அயோடின் நிறைந்த உணவுகளை சரியான முறையில் தேர்வு செய்வது தைராய்டு ஆரோக்கியத்திற்கு உதவலாம். 💚 📌 இந்த தகவல் பயனுள்ளதாக இருந்தால் Save செய்யுங்கள், Share செய்து மற்றவர்களுக்கும் தெரியப்படுத்துங்கள், மேலும் தைராய்டு குறித்து உங்களுக்கு இருக்கும் கேள்வியை Comments-ல் பதிவு செய்யுங்கள். #Thyroid #HealthyEating #Nutrition #Wellness #HealthTips #ThyroidHealth #Hypothyroidism #ThyroidDiet #GutHealth #AutoimmuneHealth #HormoneHealth #HealthyLifestyle #EatBetter | F37: Carousel - Answering Questions | G37: {=IF(F37="","",IFERROR(INDEX(Lists!$R:$R,MATCH(F37,Lists!$Q:$Q,0)),"Check Format"))} -> Carousel
G38: {=IF(F38="","",IFERROR(INDEX(Lists!$R:$R,MATCH(F38,Lists!$Q:$Q,0)),"Check Format"))}
G39: {=IF(F39="","",IFERROR(INDEX(Lists!$R:$R,MATCH(F39,Lists!$Q:$Q,0)),"Check Format"))}
G40: {=IF(F40="","",IFERROR(INDEX(Lists!$R:$R,MATCH(F40,Lists!$Q:$Q,0)),"Check Format"))}
G41: {=IF(F41="","",IFERROR(INDEX(Lists!$R:$R,MATCH(F41,Lists!$Q:$Q,0)),"Check Format"))}
G42: {=IF(F42="","",IFERROR(INDEX(Lists!$R:$R,MATCH(F42,Lists!$Q:$Q,0)),"Check Format"))}
G43: {=IF(F43="","",IFERROR(INDEX(Lists!$R:$R,MATCH(F43,Lists!$Q:$Q,0)),"Check Format"))}
G44: {=IF(F44="","",IFERROR(INDEX(Lists!$R:$R,MATCH(F44,Lists!$Q:$Q,0)),"Check Format"))}
G45: {=IF(F45="","",IFERROR(INDEX(Lists!$R:$R,MATCH(F45,Lists!$Q:$Q,0)),"Check Format"))}
G46: {=IF(F46="","",IFERROR(INDEX(Lists!$R:$R,MATCH(F46,Lists!$Q:$Q,0)),"Check Format"))}
G47: {=IF(F47="","",IFERROR(INDEX(Lists!$R:$R,MATCH(F47,Lists!$Q:$Q,0)),"Check Format"))}
G48: {=IF(F48="","",IFERROR(INDEX(Lists!$R:$R,MATCH(F48,Lists!$Q:$Q,0)),"Check Format"))}
G49: {=IF(F49="","",IFERROR(INDEX(Lists!$R:$R,MATCH(F49,Lists!$Q:$Q,0)),"Check Format"))}
... G473: {=IF(F473="","",IFERROR(INDEX(Lists!$R:$R,MATCH(F473,Lists!$Q:$Q,0)),"Check Format"))}

Sheet Overall Analytics
A1: Overall Analytics
A2: Auto-updates from Manual Entry — do not edit this sheet
A4: Total Posts | B4: Total Reels | C4: Total Carousels | D4: Total Views | E4: Total Likes
A5: =COUNTA('Manual Entry'!B2:B473) -> 36 | B5: =COUNTIF('Manual Entry'!G2:G473,"Reel") -> 16 | C5: =COUNTIF('Manual Entry'!G2:G473,"Carousel") -> 20 | D5: =SUM('Manual Entry'!I2:I473) -> 3710594 | E5: =SUM('Manual Entry'!J2:J473) -> 41996
A7: Total Comments | B7: Total Shares | C7: Total Saves | D7: Total Accounts Reached | E7: Overall Engagement Rate
A8: =SUM('Manual Entry'!K2:K473) -> 769 | B8: =SUM('Manual Entry'!L2:L473) -> 57607 | C8: =SUM('Manual Entry'!M2:M473) -> 31875 | D8: =SUM('Manual Entry'!N2:N473) -> 2985004 | E8: =IFERROR((SUM('Manual Entry'!J2:J473)+SUM('Manual Entry'!K2:K473)+SUM('Manual Entry'!L2:L473)+SUM('Manual Entry'!M2:M473))/SUM('Manual Entry'!N2:N473),0) -> 0.044303793
A13: Content Pillar Performance
A14: Pillar | B14: Total Posts | C14: Total Views | D14: Total Likes | E14: Total Comments | F14: Total Shares | G14: Avg Performance Score
A15: Diabetes | B15: =COUNTIF('Manual Entry'!D2:D473,A15) -> 2 | C15: =SUMIF('Manual Entry'!D2:D473,A15,'Manual Entry'!I2:I473) -> 179771 | D15: =SUMIF('Manual Entry'!D2:D473,A15,'Manual Entry'!J2:J473) -> 1165 | E15: =SUMIF('Manual Entry'!D2:D473,A15,'Manual Entry'!K2:K473) -> 116 | F15: =SUMIF('Manual Entry'!D2:D473,A15,'Manual Entry'!L2:L473) -> 1085 | G15: =IFERROR(AVERAGEIF(Calc!$D$2:$D$501,A15,Calc!$AJ$2:$AJ$501),0) -> 0
A16: Obesity | B16: =COUNTIF('Manual Entry'!D2:D473,A16) -> 0 | C16: =SUMIF('Manual Entry'!D2:D473,A16,'Manual Entry'!I2:I473) -> 0 | D16: =SUMIF('Manual Entry'!D2:D473,A16,'Manual Entry'!J2:J473) -> 0 | E16: =SUMIF('Manual Entry'!D2:D473,A16,'Manual Entry'!K2:K473) -> 0 | F16: =SUMIF('Manual Entry'!D2:D473,A16,'Manual Entry'!L2:L473) -> 0 | G16: =IFERROR(AVERAGEIF(Calc!$D$2:$D$501,A16,Calc!$AJ$2:$AJ$501),0) -> 0
A17: Kids | B17: =COUNTIF('Manual Entry'!D2:D473,A17) -> 0 | C17: =SUMIF('Manual Entry'!D2:D473,A17,'Manual Entry'!I2:I473) -> 0 | D17: =SUMIF('Manual Entry'!D2:D473,A17,'Manual Entry'!J2:J473) -> 0 | E17: =SUMIF('Manual Entry'!D2:D473,A17,'Manual Entry'!K2:K473) -> 0 | F17: =SUMIF('Manual Entry'!D2:D473,A17,'Manual Entry'!L2:L473) -> 0 | G17: =IFERROR(AVERAGEIF(Calc!$D$2:$D$501,A17,Calc!$AJ$2:$AJ$501),0) -> 0
A18: Nutrition Myths | B18: =COUNTIF('Manual Entry'!D2:D473,A18) -> 2 | C18: =SUMIF('Manual Entry'!D2:D473,A18,'Manual Entry'!I2:I473) -> 87042 | D18: =SUMIF('Manual Entry'!D2:D473,A18,'Manual Entry'!J2:J473) -> 1191 | E18: =SUMIF('Manual Entry'!D2:D473,A18,'Manual Entry'!K2:K473) -> 39 | F18: =SUMIF('Manual Entry'!D2:D473,A18,'Manual Entry'!L2:L473) -> 857 | G18: =IFERROR(AVERAGEIF(Calc!$D$2:$D$501,A18,Calc!$AJ$2:$AJ$501),0) -> 0
A19: Longevity | B19: =COUNTIF('Manual Entry'!D2:D473,A19) -> 0 | C19: =SUMIF('Manual Entry'!D2:D473,A19,'Manual Entry'!I2:I473) -> 0 | D19: =SUMIF('Manual Entry'!D2:D473,A19,'Manual Entry'!J2:J473) -> 0 | E19: =SUMIF('Manual Entry'!D2:D473,A19,'Manual Entry'!K2:K473) -> 0 | F19: =SUMIF('Manual Entry'!D2:D473,A19,'Manual Entry'!L2:L473) -> 0 | G19: =IFERROR(AVERAGEIF(Calc!$D$2:$D$501,A19,Calc!$AJ$2:$AJ$501),0) -> 0
A21: Best Performing Pillar: | B21: {=IF(COUNTA('Manual Entry'!B2:B473)=0,"No data yet",INDEX(A15:A19,MATCH(MAX(G15:G19),G15:G19,0)))} -> Diabetes
A24: Audience Avatar Performance
A25: Avatar | B25: Total Posts | C25: Total Views | D25: Total Likes | E25: Total Comments | F25: Total Shares | G25: Avg Performance Score
A26: Diabetes Patient | B26: =COUNTIF('Manual Entry'!H2:H473,A26) -> 0 | C26: =SUMIF('Manual Entry'!H2:H473,A26,'Manual Entry'!I2:I473) -> 0 | D26: =SUMIF('Manual Entry'!H2:H473,A26,'Manual Entry'!J2:J473) -> 0 | E26: =SUMIF('Manual Entry'!H2:H473,A26,'Manual Entry'!K2:K473) -> 0 | F26: =SUMIF('Manual Entry'!H2:H473,A26,'Manual Entry'!L2:L473) -> 0 | G26: =IFERROR(AVERAGEIF(Calc!$H$2:$H$501,A26,Calc!$AJ$2:$AJ$501),0) -> 0
A27: Parents | B27: =COUNTIF('Manual Entry'!H2:H473,A27) -> 0 | C27: =SUMIF('Manual Entry'!H2:H473,A27,'Manual Entry'!I2:I473) -> 0 | D27: =SUMIF('Manual Entry'!H2:H473,A27,'Manual Entry'!J2:J473) -> 0 | E27: =SUMIF('Manual Entry'!H2:H473,A27,'Manual Entry'!K2:K473) -> 0 | F27: =SUMIF('Manual Entry'!H2:H473,A27,'Manual Entry'!L2:L473) -> 0 | G27: =IFERROR(AVERAGEIF(Calc!$H$2:$H$501,A27,Calc!$AJ$2:$AJ$501),0) -> 0
A28: Working Professional | B28: =COUNTIF('Manual Entry'!H2:H473,A28) -> 0 | C28: =SUMIF('Manual Entry'!H2:H473,A28,'Manual Entry'!I2:I473) -> 0 | D28: =SUMIF('Manual Entry'!H2:H473,A28,'Manual Entry'!J2:J473) -> 0 | E28: =SUMIF('Manual Entry'!H2:H473,A28,'Manual Entry'!K2:K473) -> 0 | F28: =SUMIF('Manual Entry'!H2:H473,A28,'Manual Entry'!L2:L473) -> 0 | G28: =IFERROR(AVERAGEIF(Calc!$H$2:$H$501,A28,Calc!$AJ$2:$AJ$501),0) -> 0
A29: Senior Adult | B29: =COUNTIF('Manual Entry'!H2:H473,A29) -> 0 | C29: =SUMIF('Manual Entry'!H2:H473,A29,'Manual Entry'!I2:I473) -> 0 | D29: =SUMIF('Manual Entry'!H2:H473,A29,'Manual Entry'!J2:J473) -> 0 | E29: =SUMIF('Manual Entry'!H2:H473,A29,'Manual Entry'!K2:K473) -> 0 | F29: =SUMIF('Manual Entry'!H2:H473,A29,'Manual Entry'!L2:L473) -> 0 | G29: =IFERROR(AVERAGEIF(Calc!$H$2:$H$501,A29,Calc!$AJ$2:$AJ$501),0) -> 0
A30: Health Enthusiast | B30: =COUNTIF('Manual Entry'!H2:H473,A30) -> 0 | C30: =SUMIF('Manual Entry'!H2:H473,A30,'Manual Entry'!I2:I473) -> 0 | D30: =SUMIF('Manual Entry'!H2:H473,A30,'Manual Entry'!J2:J473) -> 0 | E30: =SUMIF('Manual Entry'!H2:H473,A30,'Manual Entry'!K2:K473) -> 0 | F30: =SUMIF('Manual Entry'!H2:H473,A30,'Manual Entry'!L2:L473) -> 0 | G30: =IFERROR(AVERAGEIF(Calc!$H$2:$H$501,A30,Calc!$AJ$2:$AJ$501),0) -> 0
A31: Weight Loss | B31: =COUNTIF('Manual Entry'!H2:H473,A31) -> 0 | C31: =SUMIF('Manual Entry'!H2:H473,A31,'Manual Entry'!I2:I473) -> 0 | D31: =SUMIF('Manual Entry'!H2:H473,A31,'Manual Entry'!J2:J473) -> 0 | E31: =SUMIF('Manual Entry'!H2:H473,A31,'Manual Entry'!K2:K473) -> 0 | F31: =SUMIF('Manual Entry'!H2:H473,A31,'Manual Entry'!L2:L473) -> 0 | G31: =IFERROR(AVERAGEIF(Calc!$H$2:$H$501,A31,Calc!$AJ$2:$AJ$501),0) -> 0
A32: Womens | B32: =COUNTIF('Manual Entry'!H2:H473,A32) -> 0 | C32: =SUMIF('Manual Entry'!H2:H473,A32,'Manual Entry'!I2:I473) -> 0 | D32: =SUMIF('Manual Entry'!H2:H473,A32,'Manual Entry'!J2:J473) -> 0 | E32: =SUMIF('Manual Entry'!H2:H473,A32,'Manual Entry'!K2:K473) -> 0 | F32: =SUMIF('Manual Entry'!H2:H473,A32,'Manual Entry'!L2:L473) -> 0 | G32: =IFERROR(AVERAGEIF(Calc!$H$2:$H$501,A32,Calc!$AJ$2:$AJ$501),0) -> 0
A34: Best Performing Avatar: | B34: {=IF(COUNTA('Manual Entry'!B2:B473)=0,"No data yet",INDEX(A26:A32,MATCH(MAX(G26:G32),G26:G32,0)))} -> Diabetes Patient

Sheet Best Reels
A1: Best Reels
A2: Auto-updates from Manual Entry — do not edit this sheet
A4: 🏆 Best Reel — This Week | F4: 🏆 Best Reel — This Month
A5: {=IFERROR(INDEX(Calc!$E:$E,MATCH(TEXT(TODAY()-WEEKDAY(TODAY(),2)+1,"YYYYMMDD")&"|Reel",Calc!$AL:$AL,0)),"No Reel posted this week yet")} -> Not treating Diabetes, only managaing symptoms | F5: {=IFERROR(INDEX(Calc!$E:$E,MATCH(TEXT(TODAY(),"YYYY-MM")&"|Reel",Calc!$AN:$AN,0)),"No Reel posted this month yet")} -> Tips for Effective sleep
A6: Views: | B6: Likes: | C6: Comments: | D6: Shares: | E6: Saves: | F6: Views: | G6: Likes: | H6: Comments: | I6: Shares:
A7: {=IFERROR(INDEX(Calc!$I:$I,MATCH(TEXT(TODAY()-WEEKDAY(TODAY(),2)+1,"YYYYMMDD")&"|Reel",Calc!$AL:$AL,0)),"")} -> 15096 | B7: {=IFERROR(INDEX(Calc!$J:$J,MATCH(TEXT(TODAY()-WEEKDAY(TODAY(),2)+1,"YYYYMMDD")&"|Reel",Calc!$AL:$AL,0)),"")} -> 99 | C7: {=IFERROR(INDEX(Calc!$K:$K,MATCH(TEXT(TODAY()-WEEKDAY(TODAY(),2)+1,"YYYYMMDD")&"|Reel",Calc!$AL:$AL,0)),"")} -> 0 | D7: {=IFERROR(INDEX(Calc!$L:$L,MATCH(TEXT(TODAY()-WEEKDAY(TODAY(),2)+1,"YYYYMMDD")&"|Reel",Calc!$AL:$AL,0)),"")} -> 20 | E7: {=IFERROR(INDEX(Calc!$M:$M,MATCH(TEXT(TODAY()-WEEKDAY(TODAY(),2)+1,"YYYYMMDD")&"|Reel",Calc!$AL:$AL,0)),"")} -> 21 | F7: {=IFERROR(INDEX(Calc!$I:$I,MATCH(TEXT(TODAY(),"YYYY-MM")&"|Reel",Calc!$AN:$AN,0)),"")} | G7: {=IFERROR(INDEX(Calc!$J:$J,MATCH(TEXT(TODAY(),"YYYY-MM")&"|Reel",Calc!$AN:$AN,0)),"")} -> 418 | H7: {=IFERROR(INDEX(Calc!$K:$K,MATCH(TEXT(TODAY(),"YYYY-MM")&"|Reel",Calc!$AN:$AN,0)),"")} -> 10 | I7: {=IFERROR(INDEX(Calc!$L:$L,MATCH(TEXT(TODAY(),"YYYY-MM")&"|Reel",Calc!$AN:$AN,0)),"")} -> 379
A10: Weekly Leaderboard — Best Reel Each Week (most recent first)
A11: Week Starting | B11: Title | C11: Pillar | D11: Format | E11: Avatar | F11: Views | G11: Likes | H11: Comments | I11: Shares | J11: Saves | K11: Reach | L11: Score
A12: =IFERROR(AGGREGATE(14,6,(Calc!$B$2:$B$501)/((Calc!$AK$2:$AK$501=1)*(Calc!$G$2:$G$501="Reel")),1),"") | B12: {=IF(A12="","",IFERROR(INDEX(Calc!$E:$E,MATCH(IF(A12="","",TEXT(A12,"YYYYMMDD")&"|Reel"),Calc!$AL:$AL,0)),""))} | C12: {=IF(A12="","",IFERROR(INDEX(Calc!$D:$D,MATCH(IF(A12="","",TEXT(A12,"YYYYMMDD")&"|Reel"),Calc!$AL:$AL,0)),""))} | D12: {=IF(A12="","",IFERROR(INDEX(Calc!$F:$F,MATCH(IF(A12="","",TEXT(A12,"YYYYMMDD")&"|Reel"),Calc!$AL:$AL,0)),""))} | E12: {=IF(A12="","",IFERROR(INDEX(Calc!$H:$H,MATCH(IF(A12="","",TEXT(A12,"YYYYMMDD")&"|Reel"),Calc!$AL:$AL,0)),""))} | F12: {=IF(A12="","",IFERROR(INDEX(Calc!$I:$I,MATCH(IF(A12="","",TEXT(A12,"YYYYMMDD")&"|Reel"),Calc!$AL:$AL,0)),""))} | G12: {=IF(A12="","",IFERROR(INDEX(Calc!$J:$J,MATCH(IF(A12="","",TEXT(A12,"YYYYMMDD")&"|Reel"),Calc!$AL:$AL,0)),""))} | H12: {=IF(A12="","",IFERROR(INDEX(Calc!$K:$K,MATCH(IF(A12="","",TEXT(A12,"YYYYMMDD")&"|Reel"),Calc!$AL:$AL,0)),""))} | I12: {=IF(A12="","",IFERROR(INDEX(Calc!$L:$L,MATCH(IF(A12="","",TEXT(A12,"YYYYMMDD")&"|Reel"),Calc!$AL:$AL,0)),""))} | J12: {=IF(A12="","",IFERROR(INDEX(Calc!$M:$M,MATCH(IF(A12="","",TEXT(A12,"YYYYMMDD")&"|Reel"),Calc!$AL:$AL,0)),""))} | K12: {=IF(A12="","",IFERROR(INDEX(Calc!$N:$N,MATCH(IF(A12="","",TEXT(A12,"YYYYMMDD")&"|Reel"),Calc!$AL:$AL,0)),""))} | L12: {=IF(A12="","",IFERROR(INDEX(Calc!$AH:$AH,MATCH(IF(A12="","",TEXT(A12,"YYYYMMDD")&"|Reel"),Calc!$AL:$AL,0)),""))}
A13: =IFERROR(AGGREGATE(14,6,(Calc!$B$2:$B$501)/((Calc!$AK$2:$AK$501=1)*(Calc!$G$2:$G$501="Reel")),2),"") | B13: {=IF(A13="","",IFERROR(INDEX(Calc!$E:$E,MATCH(IF(A13="","",TEXT(A13,"YYYYMMDD")&"|Reel"),Calc!$AL:$AL,0)),""))} | C13: {=IF(A13="","",IFERROR(INDEX(Calc!$D:$D,MATCH(IF(A13="","",TEXT(A13,"YYYYMMDD")&"|Reel"),Calc!$AL:$AL,0)),""))} | D13: {=IF(A13="","",IFERROR(INDEX(Calc!$F:$F,MATCH(IF(A13="","",TEXT(A13,"YYYYMMDD")&"|Reel"),Calc!$AL:$AL,0)),""))} | E13: {=IF(A13="","",IFERROR(INDEX(Calc!$H:$H,MATCH(IF(A13="","",TEXT(A13,"YYYYMMDD")&"|Reel"),Calc!$AL:$AL,0)),""))} | F13: {=IF(A13="","",IFERROR(INDEX(Calc!$I:$I,MATCH(IF(A13="","",TEXT(A13,"YYYYMMDD")&"|Reel"),Calc!$AL:$AL,0)),""))} | G13: {=IF(A13="","",IFERROR(INDEX(Calc!$J:$J,MATCH(IF(A13="","",TEXT(A13,"YYYYMMDD")&"|Reel"),Calc!$AL:$AL,0)),""))} | H13: {=IF(A13="","",IFERROR(INDEX(Calc!$K:$K,MATCH(IF(A13="","",TEXT(A13,"YYYYMMDD")&"|Reel"),Calc!$AL:$AL,0)),""))} | I13: {=IF(A13="","",IFERROR(INDEX(Calc!$L:$L,MATCH(IF(A13="","",TEXT(A13,"YYYYMMDD")&"|Reel"),Calc!$AL:$AL,0)),""))} | J13: {=IF(A13="","",IFERROR(INDEX(Calc!$M:$M,MATCH(IF(A13="","",TEXT(A13,"YYYYMMDD")&"|Reel"),Calc!$AL:$AL,0)),""))} | K13: {=IF(A13="","",IFERROR(INDEX(Calc!$N:$N,MATCH(IF(A13="","",TEXT(A13,"YYYYMMDD")&"|Reel"),Calc!$AL:$AL,0)),""))} | L13: {=IF(A13="","",IFERROR(INDEX(Calc!$AH:$AH,MATCH(IF(A13="","",TEXT(A13,"YYYYMMDD")&"|Reel"),Calc!$AL:$AL,0)),""))}
A14: =IFERROR(AGGREGATE(14,6,(Calc!$B$2:$B$501)/((Calc!$AK$2:$AK$501=1)*(Calc!$G$2:$G$501="Reel")),3),"") | B14: {=IF(A14="","",IFERROR(INDEX(Calc!$E:$E,MATCH(IF(A14="","",TEXT(A14,"YYYYMMDD")&"|Reel"),Calc!$AL:$AL,0)),""))} | C14: {=IF(A14="","",IFERROR(INDEX(Calc!$D:$D,MATCH(IF(A14="","",TEXT(A14,"YYYYMMDD")&"|Reel"),Calc!$AL:$AL,0)),""))} | D14: {=IF(A14="","",IFERROR(INDEX(Calc!$F:$F,MATCH(IF(A14="","",TEXT(A14,"YYYYMMDD")&"|Reel"),Calc!$AL:$AL,0)),""))} | E14: {=IF(A14="","",IFERROR(INDEX(Calc!$H:$H,MATCH(IF(A14="","",TEXT(A14,"YYYYMMDD")&"|Reel"),Calc!$AL:$AL,0)),""))} | F14: {=IF(A14="","",IFERROR(INDEX(Calc!$I:$I,MATCH(IF(A14="","",TEXT(A14,"YYYYMMDD")&"|Reel"),Calc!$AL:$AL,0)),""))} | G14: {=IF(A14="","",IFERROR(INDEX(Calc!$J:$J,MATCH(IF(A14="","",TEXT(A14,"YYYYMMDD")&"|Reel"),Calc!$AL:$AL,0)),""))} | H14: {=IF(A14="","",IFERROR(INDEX(Calc!$K:$K,MATCH(IF(A14="","",TEXT(A14,"YYYYMMDD")&"|Reel"),Calc!$AL:$AL,0)),""))} | I14: {=IF(A14="","",IFERROR(INDEX(Calc!$L:$L,MATCH(IF(A14="","",TEXT(A14,"YYYYMMDD")&"|Reel"),Calc!$AL:$AL,0)),""))} | J14: {=IF(A14="","",IFERROR(INDEX(Calc!$M:$M,MATCH(IF(A14="","",TEXT(A14,"YYYYMMDD")&"|Reel"),Calc!$AL:$AL,0)),""))} | K14: {=IF(A14="","",IFERROR(INDEX(Calc!$N:$N,MATCH(IF(A14="","",TEXT(A14,"YYYYMMDD")&"|Reel"),Calc!$AL:$AL,0)),""))} | L14: {=IF(A14="","",IFERROR(INDEX(Calc!$AH:$AH,MATCH(IF(A14="","",TEXT(A14,"YYYYMMDD")&"|Reel"),Calc!$AL:$AL,0)),""))}
A15: =IFERROR(AGGREGATE(14,6,(Calc!$B$2:$B$501)/((Calc!$AK$2:$AK$501=1)*(Calc!$G$2:$G$501="Reel")),4),"") | B15: {=IF(A15="","",IFERROR(INDEX(Calc!$E:$E,MATCH(IF(A15="","",TEXT(A15,"YYYYMMDD")&"|Reel"),Calc!$AL:$AL,0)),""))} | C15: {=IF(A15="","",IFERROR(INDEX(Calc!$D:$D,MATCH(IF(A15="","",TEXT(A15,"YYYYMMDD")&"|Reel"),Calc!$AL:$AL,0)),""))} | D15: {=IF(A15="","",IFERROR(INDEX(Calc!$F:$F,MATCH(IF(A15="","",TEXT(A15,"YYYYMMDD")&"|Reel"),Calc!$AL:$AL,0)),""))} | E15: {=IF(A15="","",IFERROR(INDEX(Calc!$H:$H,MATCH(IF(A15="","",TEXT(A15,"YYYYMMDD")&"|Reel"),Calc!$AL:$AL,0)),""))} | F15: {=IF(A15="","",IFERROR(INDEX(Calc!$I:$I,MATCH(IF(A15="","",TEXT(A15,"YYYYMMDD")&"|Reel"),Calc!$AL:$AL,0)),""))} | G15: {=IF(A15="","",IFERROR(INDEX(Calc!$J:$J,MATCH(IF(A15="","",TEXT(A15,"YYYYMMDD")&"|Reel"),Calc!$AL:$AL,0)),""))} | H15: {=IF(A15="","",IFERROR(INDEX(Calc!$K:$K,MATCH(IF(A15="","",TEXT(A15,"YYYYMMDD")&"|Reel"),Calc!$AL:$AL,0)),""))} | I15: {=IF(A15="","",IFERROR(INDEX(Calc!$L:$L,MATCH(IF(A15="","",TEXT(A15,"YYYYMMDD")&"|Reel"),Calc!$AL:$AL,0)),""))} | J15: {=IF(A15="","",IFERROR(INDEX(Calc!$M:$M,MATCH(IF(A15="","",TEXT(A15,"YYYYMMDD")&"|Reel"),Calc!$AL:$AL,0)),""))} | K15: {=IF(A15="","",IFERROR(INDEX(Calc!$N:$N,MATCH(IF(A15="","",TEXT(A15,"YYYYMMDD")&"|Reel"),Calc!$AL:$AL,0)),""))} | L15: {=IF(A15="","",IFERROR(INDEX(Calc!$AH:$AH,MATCH(IF(A15="","",TEXT(A15,"YYYYMMDD")&"|Reel"),Calc!$AL:$AL,0)),""))}
A16: =IFERROR(AGGREGATE(14,6,(Calc!$B$2:$B$501)/((Calc!$AK$2:$AK$501=1)*(Calc!$G$2:$G$501="Reel")),5),"") | B16: {=IF(A16="","",IFERROR(INDEX(Calc!$E:$E,MATCH(IF(A16="","",TEXT(A16,"YYYYMMDD")&"|Reel"),Calc!$AL:$AL,0)),""))} | C16: {=IF(A16="","",IFERROR(INDEX(Calc!$D:$D,MATCH(IF(A16="","",TEXT(A16,"YYYYMMDD")&"|Reel"),Calc!$AL:$AL,0)),""))} | D16: {=IF(A16="","",IFERROR(INDEX(Calc!$F:$F,MATCH(IF(A16="","",TEXT(A16,"YYYYMMDD")&"|Reel"),Calc!$AL:$AL,0)),""))} | E16: {=IF(A16="","",IFERROR(INDEX(Calc!$H:$H,MATCH(IF(A16="","",TEXT(A16,"YYYYMMDD")&"|Reel"),Calc!$AL:$AL,0)),""))} | F16: {=IF(A16="","",IFERROR(INDEX(Calc!$I:$I,MATCH(IF(A16="","",TEXT(A16,"YYYYMMDD")&"|Reel"),Calc!$AL:$AL,0)),""))} | G16: {=IF(A16="","",IFERROR(INDEX(Calc!$J:$J,MATCH(IF(A16="","",TEXT(A16,"YYYYMMDD")&"|Reel"),Calc!$AL:$AL,0)),""))} | H16: {=IF(A16="","",IFERROR(INDEX(Calc!$K:$K,MATCH(IF(A16="","",TEXT(A16,"YYYYMMDD")&"|Reel"),Calc!$AL:$AL,0)),""))} | I16: {=IF(A16="","",IFERROR(INDEX(Calc!$L:$L,MATCH(IF(A16="","",TEXT(A16,"YYYYMMDD")&"|Reel"),Calc!$AL:$AL,0)),""))} | J16: {=IF(A16="","",IFERROR(INDEX(Calc!$M:$M,MATCH(IF(A16="","",TEXT(A16,"YYYYMMDD")&"|Reel"),Calc!$AL:$AL,0)),""))} | K16: {=IF(A16="","",IFERROR(INDEX(Calc!$N:$N,MATCH(IF(A16="","",TEXT(A16,"YYYYMMDD")&"|Reel"),Calc!$AL:$AL,0)),""))} | L16: {=IF(A16="","",IFERROR(INDEX(Calc!$AH:$AH,MATCH(IF(A16="","",TEXT(A16,"YYYYMMDD")&"|Reel"),Calc!$AL:$AL,0)),""))}
A17: =IFERROR(AGGREGATE(14,6,(Calc!$B$2:$B$501)/((Calc!$AK$2:$AK$501=1)*(Calc!$G$2:$G$501="Reel")),6),"") | B17: {=IF(A17="","",IFERROR(INDEX(Calc!$E:$E,MATCH(IF(A17="","",TEXT(A17,"YYYYMMDD")&"|Reel"),Calc!$AL:$AL,0)),""))} | C17: {=IF(A17="","",IFERROR(INDEX(Calc!$D:$D,MATCH(IF(A17="","",TEXT(A17,"YYYYMMDD")&"|Reel"),Calc!$AL:$AL,0)),""))} | D17: {=IF(A17="","",IFERROR(INDEX(Calc!$F:$F,MATCH(IF(A17="","",TEXT(A17,"YYYYMMDD")&"|Reel"),Calc!$AL:$AL,0)),""))} | E17: {=IF(A17="","",IFERROR(INDEX(Calc!$H:$H,MATCH(IF(A17="","",TEXT(A17,"YYYYMMDD")&"|Reel"),Calc!$AL:$AL,0)),""))} | F17: {=IF(A17="","",IFERROR(INDEX(Calc!$I:$I,MATCH(IF(A17="","",TEXT(A17,"YYYYMMDD")&"|Reel"),Calc!$AL:$AL,0)),""))} | G17: {=IF(A17="","",IFERROR(INDEX(Calc!$J:$J,MATCH(IF(A17="","",TEXT(A17,"YYYYMMDD")&"|Reel"),Calc!$AL:$AL,0)),""))} | H17: {=IF(A17="","",IFERROR(INDEX(Calc!$K:$K,MATCH(IF(A17="","",TEXT(A17,"YYYYMMDD")&"|Reel"),Calc!$AL:$AL,0)),""))} | I17: {=IF(A17="","",IFERROR(INDEX(Calc!$L:$L,MATCH(IF(A17="","",TEXT(A17,"YYYYMMDD")&"|Reel"),Calc!$AL:$AL,0)),""))} | J17: {=IF(A17="","",IFERROR(INDEX(Calc!$M:$M,MATCH(IF(A17="","",TEXT(A17,"YYYYMMDD")&"|Reel"),Calc!$AL:$AL,0)),""))} | K17: {=IF(A17="","",IFERROR(INDEX(Calc!$N:$N,MATCH(IF(A17="","",TEXT(A17,"YYYYMMDD")&"|Reel"),Calc!$AL:$AL,0)),""))} | L17: {=IF(A17="","",IFERROR(INDEX(Calc!$AH:$AH,MATCH(IF(A17="","",TEXT(A17,"YYYYMMDD")&"|Reel"),Calc!$AL:$AL,0)),""))}
A18: =IFERROR(AGGREGATE(14,6,(Calc!$B$2:$B$501)/((Calc!$AK$2:$AK$501=1)*(Calc!$G$2:$G$501="Reel")),7),"") | B18: {=IF(A18="","",IFERROR(INDEX(Calc!$E:$E,MATCH(IF(A18="","",TEXT(A18,"YYYYMMDD")&"|Reel"),Calc!$AL:$AL,0)),""))} | C18: {=IF(A18="","",IFERROR(INDEX(Calc!$D:$D,MATCH(IF(A18="","",TEXT(A18,"YYYYMMDD")&"|Reel"),Calc!$AL:$AL,0)),""))} | D18: {=IF(A18="","",IFERROR(INDEX(Calc!$F:$F,MATCH(IF(A18="","",TEXT(A18,"YYYYMMDD")&"|Reel"),Calc!$AL:$AL,0)),""))} | E18: {=IF(A18="","",IFERROR(INDEX(Calc!$H:$H,MATCH(IF(A18="","",TEXT(A18,"YYYYMMDD")&"|Reel"),Calc!$AL:$AL,0)),""))} | F18: {=IF(A18="","",IFERROR(INDEX(Calc!$I:$I,MATCH(IF(A18="","",TEXT(A18,"YYYYMMDD")&"|Reel"),Calc!$AL:$AL,0)),""))} | G18: {=IF(A18="","",IFERROR(INDEX(Calc!$J:$J,MATCH(IF(A18="","",TEXT(A18,"YYYYMMDD")&"|Reel"),Calc!$AL:$AL,0)),""))} | H18: {=IF(A18="","",IFERROR(INDEX(Calc!$K:$K,MATCH(IF(A18="","",TEXT(A18,"YYYYMMDD")&"|Reel"),Calc!$AL:$AL,0)),""))} | I18: {=IF(A18="","",IFERROR(INDEX(Calc!$L:$L,MATCH(IF(A18="","",TEXT(A18,"YYYYMMDD")&"|Reel"),Calc!$AL:$AL,0)),""))} | J18: {=IF(A18="","",IFERROR(INDEX(Calc!$M:$M,MATCH(IF(A18="","",TEXT(A18,"YYYYMMDD")&"|Reel"),Calc!$AL:$AL,0)),""))} | K18: {=IF(A18="","",IFERROR(INDEX(Calc!$N:$N,MATCH(IF(A18="","",TEXT(A18,"YYYYMMDD")&"|Reel"),Calc!$AL:$AL,0)),""))} | L18: {=IF(A18="","",IFERROR(INDEX(Calc!$AH:$AH,MATCH(IF(A18="","",TEXT(A18,"YYYYMMDD")&"|Reel"),Calc!$AL:$AL,0)),""))}
A19: =IFERROR(AGGREGATE(14,6,(Calc!$B$2:$B$501)/((Calc!$AK$2:$AK$501=1)*(Calc!$G$2:$G$501="Reel")),8),"") | B19: {=IF(A19="","",IFERROR(INDEX(Calc!$E:$E,MATCH(IF(A19="","",TEXT(A19,"YYYYMMDD")&"|Reel"),Calc!$AL:$AL,0)),""))} | C19: {=IF(A19="","",IFERROR(INDEX(Calc!$D:$D,MATCH(IF(A19="","",TEXT(A19,"YYYYMMDD")&"|Reel"),Calc!$AL:$AL,0)),""))} | D19: {=IF(A19="","",IFERROR(INDEX(Calc!$F:$F,MATCH(IF(A19="","",TEXT(A19,"YYYYMMDD")&"|Reel"),Calc!$AL:$AL,0)),""))} | E19: {=IF(A19="","",IFERROR(INDEX(Calc!$H:$H,MATCH(IF(A19="","",TEXT(A19,"YYYYMMDD")&"|Reel"),Calc!$AL:$AL,0)),""))} | F19: {=IF(A19="","",IFERROR(INDEX(Calc!$I:$I,MATCH(IF(A19="","",TEXT(A19,"YYYYMMDD")&"|Reel"),Calc!$AL:$AL,0)),""))} | G19: {=IF(A19="","",IFERROR(INDEX(Calc!$J:$J,MATCH(IF(A19="","",TEXT(A19,"YYYYMMDD")&"|Reel"),Calc!$AL:$AL,0)),""))} | H19: {=IF(A19="","",IFERROR(INDEX(Calc!$K:$K,MATCH(IF(A19="","",TEXT(A19,"YYYYMMDD")&"|Reel"),Calc!$AL:$AL,0)),""))} | I19: {=IF(A19="","",IFERROR(INDEX(Calc!$L:$L,MATCH(IF(A19="","",TEXT(A19,"YYYYMMDD")&"|Reel"),Calc!$AL:$AL,0)),""))} | J19: {=IF(A19="","",IFERROR(INDEX(Calc!$M:$M,MATCH(IF(A19="","",TEXT(A19,"YYYYMMDD")&"|Reel"),Calc!$AL:$AL,0)),""))} | K19: {=IF(A19="","",IFERROR(INDEX(Calc!$N:$N,MATCH(IF(A19="","",TEXT(A19,"YYYYMMDD")&"|Reel"),Calc!$AL:$AL,0)),""))} | L19: {=IF(A19="","",IFERROR(INDEX(Calc!$AH:$AH,MATCH(IF(A19="","",TEXT(A19,"YYYYMMDD")&"|Reel"),Calc!$AL:$AL,0)),""))}
A20: =IFERROR(AGGREGATE(14,6,(Calc!$B$2:$B$501)/((Calc!$AK$2:$AK$501=1)*(Calc!$G$2:$G$501="Reel")),9),"") | B20: {=IF(A20="","",IFERROR(INDEX(Calc!$E:$E,MATCH(IF(A20="","",TEXT(A20,"YYYYMMDD")&"|Reel"),Calc!$AL:$AL,0)),""))} | C20: {=IF(A20="","",IFERROR(INDEX(Calc!$D:$D,MATCH(IF(A20="","",TEXT(A20,"YYYYMMDD")&"|Reel"),Calc!$AL:$AL,0)),""))} | D20: {=IF(A20="","",IFERROR(INDEX(Calc!$F:$F,MATCH(IF(A20="","",TEXT(A20,"YYYYMMDD")&"|Reel"),Calc!$AL:$AL,0)),""))} | E20: {=IF(A20="","",IFERROR(INDEX(Calc!$H:$H,MATCH(IF(A20="","",TEXT(A20,"YYYYMMDD")&"|Reel"),Calc!$AL:$AL,0)),""))} | F20: {=IF(A20="","",IFERROR(INDEX(Calc!$I:$I,MATCH(IF(A20="","",TEXT(A20,"YYYYMMDD")&"|Reel"),Calc!$AL:$AL,0)),""))} | G20: {=IF(A20="","",IFERROR(INDEX(Calc!$J:$J,MATCH(IF(A20="","",TEXT(A20,"YYYYMMDD")&"|Reel"),Calc!$AL:$AL,0)),""))} | H20: {=IF(A20="","",IFERROR(INDEX(Calc!$K:$K,MATCH(IF(A20="","",TEXT(A20,"YYYYMMDD")&"|Reel"),Calc!$AL:$AL,0)),""))} | I20: {=IF(A20="","",IFERROR(INDEX(Calc!$L:$L,MATCH(IF(A20="","",TEXT(A20,"YYYYMMDD")&"|Reel"),Calc!$AL:$AL,0)),""))} | J20: {=IF(A20="","",IFERROR(INDEX(Calc!$M:$M,MATCH(IF(A20="","",TEXT(A20,"YYYYMMDD")&"|Reel"),Calc!$AL:$AL,0)),""))} | K20: {=IF(A20="","",IFERROR(INDEX(Calc!$N:$N,MATCH(IF(A20="","",TEXT(A20,"YYYYMMDD")&"|Reel"),Calc!$AL:$AL,0)),""))} | L20: {=IF(A20="","",IFERROR(INDEX(Calc!$AH:$AH,MATCH(IF(A20="","",TEXT(A20,"YYYYMMDD")&"|Reel"),Calc!$AL:$AL,0)),""))}
A21: =IFERROR(AGGREGATE(14,6,(Calc!$B$2:$B$501)/((Calc!$AK$2:$AK$501=1)*(Calc!$G$2:$G$501="Reel")),10),"") | B21: {=IF(A21="","",IFERROR(INDEX(Calc!$E:$E,MATCH(IF(A21="","",TEXT(A21,"YYYYMMDD")&"|Reel"),Calc!$AL:$AL,0)),""))} | C21: {=IF(A21="","",IFERROR(INDEX(Calc!$D:$D,MATCH(IF(A21="","",TEXT(A21,"YYYYMMDD")&"|Reel"),Calc!$AL:$AL,0)),""))} | D21: {=IF(A21="","",IFERROR(INDEX(Calc!$F:$F,MATCH(IF(A21="","",TEXT(A21,"YYYYMMDD")&"|Reel"),Calc!$AL:$AL,0)),""))} | E21: {=IF(A21="","",IFERROR(INDEX(Calc!$H:$H,MATCH(IF(A21="","",TEXT(A21,"YYYYMMDD")&"|Reel"),Calc!$AL:$AL,0)),""))} | F21: {=IF(A21="","",IFERROR(INDEX(Calc!$I:$I,MATCH(IF(A21="","",TEXT(A21,"YYYYMMDD")&"|Reel"),Calc!$AL:$AL,0)),""))} | G21: {=IF(A21="","",IFERROR(INDEX(Calc!$J:$J,MATCH(IF(A21="","",TEXT(A21,"YYYYMMDD")&"|Reel"),Calc!$AL:$AL,0)),""))} | H21: {=IF(A21="","",IFERROR(INDEX(Calc!$K:$K,MATCH(IF(A21="","",TEXT(A21,"YYYYMMDD")&"|Reel"),Calc!$AL:$AL,0)),""))} | I21: {=IF(A21="","",IFERROR(INDEX(Calc!$L:$L,MATCH(IF(A21="","",TEXT(A21,"YYYYMMDD")&"|Reel"),Calc!$AL:$AL,0)),""))} | J21: {=IF(A21="","",IFERROR(INDEX(Calc!$M:$M,MATCH(IF(A21="","",TEXT(A21,"YYYYMMDD")&"|Reel"),Calc!$AL:$AL,0)),""))} | K21: {=IF(A21="","",IFERROR(INDEX(Calc!$N:$N,MATCH(IF(A21="","",TEXT(A21,"YYYYMMDD")&"|Reel"),Calc!$AL:$AL,0)),""))} | L21: {=IF(A21="","",IFERROR(INDEX(Calc!$AH:$AH,MATCH(IF(A21="","",TEXT(A21,"YYYYMMDD")&"|Reel"),Calc!$AL:$AL,0)),""))}
A22: =IFERROR(AGGREGATE(14,6,(Calc!$B$2:$B$501)/((Calc!$AK$2:$AK$501=1)*(Calc!$G$2:$G$501="Reel")),11),"") | B22: {=IF(A22="","",IFERROR(INDEX(Calc!$E:$E,MATCH(IF(A22="","",TEXT(A22,"YYYYMMDD")&"|Reel"),Calc!$AL:$AL,0)),""))} | C22: {=IF(A22="","",IFERROR(INDEX(Calc!$D:$D,MATCH(IF(A22="","",TEXT(A22,"YYYYMMDD")&"|Reel"),Calc!$AL:$AL,0)),""))} | D22: {=IF(A22="","",IFERROR(INDEX(Calc!$F:$F,MATCH(IF(A22="","",TEXT(A22,"YYYYMMDD")&"|Reel"),Calc!$AL:$AL,0)),""))} | E22: {=IF(A22="","",IFERROR(INDEX(Calc!$H:$H,MATCH(IF(A22="","",TEXT(A22,"YYYYMMDD")&"|Reel"),Calc!$AL:$AL,0)),""))} | F22: {=IF(A22="","",IFERROR(INDEX(Calc!$I:$I,MATCH(IF(A22="","",TEXT(A22,"YYYYMMDD")&"|Reel"),Calc!$AL:$AL,0)),""))} | G22: {=IF(A22="","",IFERROR(INDEX(Calc!$J:$J,MATCH(IF(A22="","",TEXT(A22,"YYYYMMDD")&"|Reel"),Calc!$AL:$AL,0)),""))} | H22: {=IF(A22="","",IFERROR(INDEX(Calc!$K:$K,MATCH(IF(A22="","",TEXT(A22,"YYYYMMDD")&"|Reel"),Calc!$AL:$AL,0)),""))} | I22: {=IF(A22="","",IFERROR(INDEX(Calc!$L:$L,MATCH(IF(A22="","",TEXT(A22,"YYYYMMDD")&"|Reel"),Calc!$AL:$AL,0)),""))} | J22: {=IF(A22="","",IFERROR(INDEX(Calc!$M:$M,MATCH(IF(A22="","",TEXT(A22,"YYYYMMDD")&"|Reel"),Calc!$AL:$AL,0)),""))} | K22: {=IF(A22="","",IFERROR(INDEX(Calc!$N:$N,MATCH(IF(A22="","",TEXT(A22,"YYYYMMDD")&"|Reel"),Calc!$AL:$AL,0)),""))} | L22: {=IF(A22="","",IFERROR(INDEX(Calc!$AH:$AH,MATCH(IF(A22="","",TEXT(A22,"YYYYMMDD")&"|Reel"),Calc!$AL:$AL,0)),""))}
A23: =IFERROR(AGGREGATE(14,6,(Calc!$B$2:$B$501)/((Calc!$AK$2:$AK$501=1)*(Calc!$G$2:$G$501="Reel")),12),"") | B23: {=IF(A23="","",IFERROR(INDEX(Calc!$E:$E,MATCH(IF(A23="","",TEXT(A23,"YYYYMMDD")&"|Reel"),Calc!$AL:$AL,0)),""))} | C23: {=IF(A23="","",IFERROR(INDEX(Calc!$D:$D,MATCH(IF(A23="","",TEXT(A23,"YYYYMMDD")&"|Reel"),Calc!$AL:$AL,0)),""))} | D23: {=IF(A23="","",IFERROR(INDEX(Calc!$F:$F,MATCH(IF(A23="","",TEXT(A23,"YYYYMMDD")&"|Reel"),Calc!$AL:$AL,0)),""))} | E23: {=IF(A23="","",IFERROR(INDEX(Calc!$H:$H,MATCH(IF(A23="","",TEXT(A23,"YYYYMMDD")&"|Reel"),Calc!$AL:$AL,0)),""))} | F23: {=IF(A23="","",IFERROR(INDEX(Calc!$I:$I,MATCH(IF(A23="","",TEXT(A23,"YYYYMMDD")&"|Reel"),Calc!$AL:$AL,0)),""))} | G23: {=IF(A23="","",IFERROR(INDEX(Calc!$J:$J,MATCH(IF(A23="","",TEXT(A23,"YYYYMMDD")&"|Reel"),Calc!$AL:$AL,0)),""))} | H23: {=IF(A23="","",IFERROR(INDEX(Calc!$K:$K,MATCH(IF(A23="","",TEXT(A23,"YYYYMMDD")&"|Reel"),Calc!$AL:$AL,0)),""))} | I23: {=IF(A23="","",IFERROR(INDEX(Calc!$L:$L,MATCH(IF(A23="","",TEXT(A23,"YYYYMMDD")&"|Reel"),Calc!$AL:$AL,0)),""))} | J23: {=IF(A23="","",IFERROR(INDEX(Calc!$M:$M,MATCH(IF(A23="","",TEXT(A23,"YYYYMMDD")&"|Reel"),Calc!$AL:$AL,0)),""))} | K23: {=IF(A23="","",IFERROR(INDEX(Calc!$N:$N,MATCH(IF(A23="","",TEXT(A23,"YYYYMMDD")&"|Reel"),Calc!$AL:$AL,0)),""))} | L23: {=IF(A23="","",IFERROR(INDEX(Calc!$AH:$AH,MATCH(IF(A23="","",TEXT(A23,"YYYYMMDD")&"|Reel"),Calc!$AL:$AL,0)),""))}
A24: =IFERROR(AGGREGATE(14,6,(Calc!$B$2:$B$501)/((Calc!$AK$2:$AK$501=1)*(Calc!$G$2:$G$501="Reel")),13),"") | B24: {=IF(A24="","",IFERROR(INDEX(Calc!$E:$E,MATCH(IF(A24="","",TEXT(A24,"YYYYMMDD")&"|Reel"),Calc!$AL:$AL,0)),""))} | C24: {=IF(A24="","",IFERROR(INDEX(Calc!$D:$D,MATCH(IF(A24="","",TEXT(A24,"YYYYMMDD")&"|Reel"),Calc!$AL:$AL,0)),""))} | D24: {=IF(A24="","",IFERROR(INDEX(Calc!$F:$F,MATCH(IF(A24="","",TEXT(A24,"YYYYMMDD")&"|Reel"),Calc!$AL:$AL,0)),""))} | E24: {=IF(A24="","",IFERROR(INDEX(Calc!$H:$H,MATCH(IF(A24="","",TEXT(A24,"YYYYMMDD")&"|Reel"),Calc!$AL:$AL,0)),""))} | F24: {=IF(A24="","",IFERROR(INDEX(Calc!$I:$I,MATCH(IF(A24="","",TEXT(A24,"YYYYMMDD")&"|Reel"),Calc!$AL:$AL,0)),""))} | G24: {=IF(A24="","",IFERROR(INDEX(Calc!$J:$J,MATCH(IF(A24="","",TEXT(A24,"YYYYMMDD")&"|Reel"),Calc!$AL:$AL,0)),""))} | H24: {=IF(A24="","",IFERROR(INDEX(Calc!$K:$K,MATCH(IF(A24="","",TEXT(A24,"YYYYMMDD")&"|Reel"),Calc!$AL:$AL,0)),""))} | I24: {=IF(A24="","",IFERROR(INDEX(Calc!$L:$L,MATCH(IF(A24="","",TEXT(A24,"YYYYMMDD")&"|Reel"),Calc!$AL:$AL,0)),""))} | J24: {=IF(A24="","",IFERROR(INDEX(Calc!$M:$M,MATCH(IF(A24="","",TEXT(A24,"YYYYMMDD")&"|Reel"),Calc!$AL:$AL,0)),""))} | K24: {=IF(A24="","",IFERROR(INDEX(Calc!$N:$N,MATCH(IF(A24="","",TEXT(A24,"YYYYMMDD")&"|Reel"),Calc!$AL:$AL,0)),""))} | L24: {=IF(A24="","",IFERROR(INDEX(Calc!$AH:$AH,MATCH(IF(A24="","",TEXT(A24,"YYYYMMDD")&"|Reel"),Calc!$AL:$AL,0)),""))}
A25: =IFERROR(AGGREGATE(14,6,(Calc!$B$2:$B$501)/((Calc!$AK$2:$AK$501=1)*(Calc!$G$2:$G$501="Reel")),14),"") | B25: {=IF(A25="","",IFERROR(INDEX(Calc!$E:$E,MATCH(IF(A25="","",TEXT(A25,"YYYYMMDD")&"|Reel"),Calc!$AL:$AL,0)),""))} | C25: {=IF(A25="","",IFERROR(INDEX(Calc!$D:$D,MATCH(IF(A25="","",TEXT(A25,"YYYYMMDD")&"|Reel"),Calc!$AL:$AL,0)),""))} | D25: {=IF(A25="","",IFERROR(INDEX(Calc!$F:$F,MATCH(IF(A25="","",TEXT(A25,"YYYYMMDD")&"|Reel"),Calc!$AL:$AL,0)),""))} | E25: {=IF(A25="","",IFERROR(INDEX(Calc!$H:$H,MATCH(IF(A25="","",TEXT(A25,"YYYYMMDD")&"|Reel"),Calc!$AL:$AL,0)),""))} | F25: {=IF(A25="","",IFERROR(INDEX(Calc!$I:$I,MATCH(IF(A25="","",TEXT(A25,"YYYYMMDD")&"|Reel"),Calc!$AL:$AL,0)),""))} | G25: {=IF(A25="","",IFERROR(INDEX(Calc!$J:$J,MATCH(IF(A25="","",TEXT(A25,"YYYYMMDD")&"|Reel"),Calc!$AL:$AL,0)),""))} | H25: {=IF(A25="","",IFERROR(INDEX(Calc!$K:$K,MATCH(IF(A25="","",TEXT(A25,"YYYYMMDD")&"|Reel"),Calc!$AL:$AL,0)),""))} | I25: {=IF(A25="","",IFERROR(INDEX(Calc!$L:$L,MATCH(IF(A25="","",TEXT(A25,"YYYYMMDD")&"|Reel"),Calc!$AL:$AL,0)),""))} | J25: {=IF(A25="","",IFERROR(INDEX(Calc!$M:$M,MATCH(IF(A25="","",TEXT(A25,"YYYYMMDD")&"|Reel"),Calc!$AL:$AL,0)),""))} | K25: {=IF(A25="","",IFERROR(INDEX(Calc!$N:$N,MATCH(IF(A25="","",TEXT(A25,"YYYYMMDD")&"|Reel"),Calc!$AL:$AL,0)),""))} | L25: {=IF(A25="","",IFERROR(INDEX(Calc!$AH:$AH,MATCH(IF(A25="","",TEXT(A25,"YYYYMMDD")&"|Reel"),Calc!$AL:$AL,0)),""))}
A26: =IFERROR(AGGREGATE(14,6,(Calc!$B$2:$B$501)/((Calc!$AK$2:$AK$501=1)*(Calc!$G$2:$G$501="Reel")),15),"") | B26: {=IF(A26="","",IFERROR(INDEX(Calc!$E:$E,MATCH(IF(A26="","",TEXT(A26,"YYYYMMDD")&"|Reel"),Calc!$AL:$AL,0)),""))} | C26: {=IF(A26="","",IFERROR(INDEX(Calc!$D:$D,MATCH(IF(A26="","",TEXT(A26,"YYYYMMDD")&"|Reel"),Calc!$AL:$AL,0)),""))} | D26: {=IF(A26="","",IFERROR(INDEX(Calc!$F:$F,MATCH(IF(A26="","",TEXT(A26,"YYYYMMDD")&"|Reel"),Calc!$AL:$AL,0)),""))} | E26: {=IF(A26="","",IFERROR(INDEX(Calc!$H:$H,MATCH(IF(A26="","",TEXT(A26,"YYYYMMDD")&"|Reel"),Calc!$AL:$AL,0)),""))} | F26: {=IF(A26="","",IFERROR(INDEX(Calc!$I:$I,MATCH(IF(A26="","",TEXT(A26,"YYYYMMDD")&"|Reel"),Calc!$AL:$AL,0)),""))} | G26: {=IF(A26="","",IFERROR(INDEX(Calc!$J:$J,MATCH(IF(A26="","",TEXT(A26,"YYYYMMDD")&"|Reel"),Calc!$AL:$AL,0)),""))} | H26: {=IF(A26="","",IFERROR(INDEX(Calc!$K:$K,MATCH(IF(A26="","",TEXT(A26,"YYYYMMDD")&"|Reel"),Calc!$AL:$AL,0)),""))} | I26: {=IF(A26="","",IFERROR(INDEX(Calc!$L:$L,MATCH(IF(A26="","",TEXT(A26,"YYYYMMDD")&"|Reel"),Calc!$AL:$AL,0)),""))} | J26: {=IF(A26="","",IFERROR(INDEX(Calc!$M:$M,MATCH(IF(A26="","",TEXT(A26,"YYYYMMDD")&"|Reel"),Calc!$AL:$AL,0)),""))} | K26: {=IF(A26="","",IFERROR(INDEX(Calc!$N:$N,MATCH(IF(A26="","",TEXT(A26,"YYYYMMDD")&"|Reel"),Calc!$AL:$AL,0)),""))} | L26: {=IF(A26="","",IFERROR(INDEX(Calc!$AH:$AH,MATCH(IF(A26="","",TEXT(A26,"YYYYMMDD")&"|Reel"),Calc!$AL:$AL,0)),""))}
A27: =IFERROR(AGGREGATE(14,6,(Calc!$B$2:$B$501)/((Calc!$AK$2:$AK$501=1)*(Calc!$G$2:$G$501="Reel")),16),"") | B27: {=IF(A27="","",IFERROR(INDEX(Calc!$E:$E,MATCH(IF(A27="","",TEXT(A27,"YYYYMMDD")&"|Reel"),Calc!$AL:$AL,0)),""))} | C27: {=IF(A27="","",IFERROR(INDEX(Calc!$D:$D,MATCH(IF(A27="","",TEXT(A27,"YYYYMMDD")&"|Reel"),Calc!$AL:$AL,0)),""))} | D27: {=IF(A27="","",IFERROR(INDEX(Calc!$F:$F,MATCH(IF(A27="","",TEXT(A27,"YYYYMMDD")&"|Reel"),Calc!$AL:$AL,0)),""))} | E27: {=IF(A27="","",IFERROR(INDEX(Calc!$H:$H,MATCH(IF(A27="","",TEXT(A27,"YYYYMMDD")&"|Reel"),Calc!$AL:$AL,0)),""))} | F27: {=IF(A27="","",IFERROR(INDEX(Calc!$I:$I,MATCH(IF(A27="","",TEXT(A27,"YYYYMMDD")&"|Reel"),Calc!$AL:$AL,0)),""))} | G27: {=IF(A27="","",IFERROR(INDEX(Calc!$J:$J,MATCH(IF(A27="","",TEXT(A27,"YYYYMMDD")&"|Reel"),Calc!$AL:$AL,0)),""))} | H27: {=IF(A27="","",IFERROR(INDEX(Calc!$K:$K,MATCH(IF(A27="","",TEXT(A27,"YYYYMMDD")&"|Reel"),Calc!$AL:$AL,0)),""))} | I27: {=IF(A27="","",IFERROR(INDEX(Calc!$L:$L,MATCH(IF(A27="","",TEXT(A27,"YYYYMMDD")&"|Reel"),Calc!$AL:$AL,0)),""))} | J27: {=IF(A27="","",IFERROR(INDEX(Calc!$M:$M,MATCH(IF(A27="","",TEXT(A27,"YYYYMMDD")&"|Reel"),Calc!$AL:$AL,0)),""))} | K27: {=IF(A27="","",IFERROR(INDEX(Calc!$N:$N,MATCH(IF(A27="","",TEXT(A27,"YYYYMMDD")&"|Reel"),Calc!$AL:$AL,0)),""))} | L27: {=IF(A27="","",IFERROR(INDEX(Calc!$AH:$AH,MATCH(IF(A27="","",TEXT(A27,"YYYYMMDD")&"|Reel"),Calc!$AL:$AL,0)),""))}
